Workbook
Name _MO: 'Naming ranges'!$C$7:$C$13
Name Alphabets: 'Dependent dropdown'!$G$3:$G$10
Name antennas: 'Scenario manager'!$E$10
Name button: 'Scenario manager'!#REF!
Name charg.port: 'Scenario manager'!$E$9
Name cooling: 'Scenario manager'!$E$14
Name Digitizer: 'Scenario manager'!$E$5
Name GRADES: 'Data for dropdown'!$F$4:$F$10
Name mic: 'Scenario manager'!$E$7
Name MO: 'Naming ranges'!$C$9
Name Month: 'Naming ranges'!$C$7:$C$14
Name MONTHSPRODUCTS: 'Naming ranges'!$C$6:$E$14
Name NativeTimeline_Date: #N/A
Name Numbers: 'Dependent dropdown'!$H$3:$H$10
Name Product: 'Naming ranges'!$D$7:$D$14
Name Sales: #REF!
Name Sceen: 'Scenario manager'!#REF!
Name screen: 'Scenario manager'!$E$4
Name simtray: 'Scenario manager'!$E$11
Name Slicer_Products: #N/A
Name Slicer_Region: #N/A
Name speaker: 'Scenario manager'!$E$6
Name Symbols: 'Dependent dropdown'!$I$3:$I$10
Name Total: 'Data Table'!#REF!
Name Type_of_data: 'Dependent dropdown'!#REF!
Name vibr.motor: 'Scenario manager'!$E$13

Sheet Split (and freeze)
B2: Date | C2: Region | D2: Items | E2: Price | H2: Date | I2: Region | J2: Items | K2: Price
B3: 36531 | C3: East | D3: Footwear | E3: 12000 | H3: 36531 | I3: East | J3: Footwear | K3: 12000
B4: 36542 | C4: East | D4: Mobile | E4: 35700 | H4: 36542 | I4: East | J4: Mobile | K4: 35700
B5: 36535 | C5: East | D5: Mobile | E5: 42840 | H5: 36535 | I5: East | J5: Mobile | K5: 42840
B6: 36530 | C6: East | D6: Smartwatch | E6: 10000 | H6: 36530 | I6: East | J6: Smartwatch | K6: 10000
B7: 36531 | C7: East | D7: Smartwatch | E7: 30000 | H7: 36531 | I7: East | J7: Smartwatch | K7: 30000
B8: 36533 | C8: North | D8: Bass Headphones | E8: 32640 | H8: 36533 | I8: North | J8: Bass Headphones | K8: 32640
B9: 36526 | C9: North | D9: Beard trimmer | E9: 4000 | H9: 36526 | I9: North | J9: Beard trimmer | K9: 4000
B10: 36528 | C10: North | D10: Deodarant | E10: 8000 | H10: 36528 | I10: North | J10: Deodarant | K10: 8000
B11: 36544 | C11: North | D11: Deodarant | E11: 8000 | H11: 36544 | I11: North | J11: Deodarant | K11: 8000
B12: 36541 | C12: North | D12: Mobile | E12: 42840 | H12: 36541 | I12: North | J12: Mobile | K12: 42840
B13: 36545 | C13: North | D13: Shaving cream | E13: 8000 | H13: 36545 | I13: North | J13: Shaving cream | K13: 8000
B14: 36534 | C14: North | D14: Wrist watch | E14: 48960 | H14: 36534 | I14: North | J14: Wrist watch | K14: 48960
... B26: 36529 | C26: West | D26: Shaving cream | E26: 8000 | H26: 36529 | I26: West | J26: Shaving cream | K26: 8000
F32: 36538 | G32: South | H32: Earbuds
F33: 36537 | G33: South | H33: Jackets

Sheet FORMULAS AND FUNCTIONS
B2: Month | C2: Product | D2: Sales
B3: January | C3: Pencils | D3: 1000 | F3: 50 | G3: =SUM(F3,F5,F7,F9) -> 240 | H3: SUM | J3: COUNT | K3: =COUNT(G3:G8) -> 6
B4: February | C4: Books | D4: 5000 | E4: 40 | G4: =SUM(E4,E6,E8) -> 200 | H4: SUM | J4: COUNT | K4: =COUNT(C3:C9) -> 0
B5: March | C5: Colors | D5: 1000 | F5: 10 | G5: =AVERAGE(F3,F7,F9,F5) -> 60 | H5: AVERAGE
B6: April | C6: Highlighters | D6: 3500 | E6: 70 | G6: =AVERAGE(E4,E6,E8) -> 66.666667 | H6: AVERAGE | J6: COUNTA | K6: =COUNTA(H3:H8) -> 6
B7: May | C7: Scales/Rulers | D7: 3000 | F7: 80 | G7: =PRODUCT(E4,E6,E8) -> 252000 | H7: PRODUCT | J7: COUNTA | K7: =COUNTA(G3:H8) -> 12
B8: June | C8: Notebooks | D8: 4000 | E8: 90 | G8: =PRODUCT(F3,F5,F7) -> 40000 | H8: PRODUCT | J8: COUNTA | K8: =COUNTA(F3:H8) -> 15
B9: July | C9: Magazines | D9: 4000 | F9: 100
B10: Total | D10: =SUM(D3:D9) -> 21500 | E10: =SUM(E3:E9) -> 200 | J10: COUNTBLANK | K10: =COUNTBLANK(H3:H8) -> 0
J11: COUNTBLANK | K11: =COUNTBLANK(J3:J9) -> 2
C12: MINIMUM | D12: =MIN(D3:D9) -> 1000 | G12: MINIMUM | H12: =MIN(F3:F9) -> 10 | J12: COUNTBLANK | K12: =COUNTBLANK(D3:E9) -> 4
C13: MAXIMUM | D13: =MAX(D3:D9) -> 5000 | G13: MAXIMUM | H13: =MAX(F3:F9) -> 100

Sheet goto, go to special
B2: Month | C2: Product | D2: Sales
B3: January | C3: Pencils | D3: 1000 | F3: 10 | I3: =SUM(#REF!) -> #REF!
B4: February | C4: Books | D4: 5000 | F4: 90
B5: March | C5: Colors | D5: 1000 | F5: 70
B6: April | C6: Highlighters | D6: 3500 | F6: 50
B7: May | C7: Scales/Rulers | D7: 3000 | F7: 40 | I7: =SUM(#REF!) -> #REF!
B8: June | C8: Notebooks | D8: 4000 | F8: 23
B9: July | C9: Magazines | D9: 4000 | F9: 50
B10: Total | D10: =SUM(D3:D9) -> 21500 | F10: =SUM(F3:F9) -> 333
B13: {={"red","white","green"}} -> red | C13: white | D13: green
B18: SUSHANT SHARMA | C18: JOHN JACOBS
B20: aiYSHA SINHA | C20: ALISHA GADGE
B22: ARNAV KUMAR
C23: SUSHANT SHARMA
H30: fgh

Sheet find, replace
B2: Month | C2: Product | D2: Sales
B3: January | C3: Pens | D3: 1000 | F3: 100 | I3: =SUM(#REF!) -> #REF!
B4: February | C4: Pens | D4: 5000 | F4: 90
B5: March | C5: Colors | D5: 1000 | F5: 70
B6: April | C6: Highlighters | D6: 3500 | F6: 60
B7: May | C7: Scales/Rulers | D7: 3000 | F7: 40 | I7: =SUM(#REF!) -> #REF!
B8: June | C8: books | D8: 4000 | F8: 23
B9: August | C9: Magazines | D9: 4000 | F9: 60
B10: Total | D10: =SUM(D3:D9) -> 21500 | F10: =SUM(F3:F9) -> 443
F15: Magazines
D16: books
A17: Pens
I18: Pens
E23: February
C25: february
I26: August
D31: January
D32: February
D33: March
D34: April
D35: May
D36: June
D37: August
D38: Total

Sheet VIsible cells only
A1: Month | B1: Product | C1: Sales
A2: February | B2: Books | C2: 5000 | E2: 90
A3: April | B3: Highlighters | C3: 3500 | E3: 50
A4: June | B4: Notebooks | C4: 4000 | E4: 23
A5: July | B5: Magazines | C5: 4000 | E5: 50
A6: Total | C6: 21500 | E6: 333

Sheet FILL - down right flash
E2: 1 | F2: 2 | G2: 3 | H2: 4 | I2: 5 | J2: 6 | K2: 7 | L2: 8 | M2: 9 | N2: 10 | O2: 11 | P2: 12 | Q2: 13 | R2: 14 | S2: 15 | T2: 16 | U2: 17 | V2: 18 | W2: 19 | X2: 20 | Y2: 21 | Z2: 22 | AA2: 23 | AB2: 24 | AC2: 25 | AD2: 26 | AE2: 27 | AF2: 28 | AG2: 29 | AH2: 30 | AI2: 31 | AJ2: 32 | AK2: 33 | AL2: 34
E3: 2
E4: 3
E5: 4 | G5: but | H5: and | I5: not | J5: but | K5: and | L5: not | M5: but | N5: and | O5: not | P5: but | Q5: and | R5: not | S5: but | T5: and | U5: not | V5: but | W5: and | X5: not | Y5: but | Z5: and | AA5: not | AB5: but | AC5: and | AD5: not | AE5: but | AF5: and | AG5: not | AH5: but | AI5: and | AJ5: not
E6: 5 | G6: but
E7: 6 | G7: but | J7: 12
E8: 7 | G8: but
E9: 8 | G9: but
E10: 9 | G10: but
E11: 10 | G11: but
E12: 11 | G12: but
E13: 12 | G13: but
E14: 13 | G14: but
E15: 14 | G15: but
E16: 15 | G16: but
E17: 16
E18: 17
E19: 18
E20: 19
E21: 20
B22: Full Name | C22: First name | D22: Last Name | L22: 5 | M22: 5 | N22: 5 | O22: 5 | P22: 5 | Q22: 5 | R22: 5 | S22: 5 | T22: 5 | U22: 5 | V22: 5 | W22: 5 | X22: 5 | Y22: 5 | Z22: 5 | AA22: 5 | AB22: 5 | AC22: 5 | AD22: 5 | AE22: 5 | AF22: 5
B23: Steve Harvey | C23: Steve | D23: Harvey | L23: 5
B24: Reshma Malik | C24: Reshma | D24: Malik | L24: 5
B25: Garris Johnson | C25: Garris | D25: Johnson | L25: 5
B26: Sanjay Gupta | C26: Sanjay | D26: Gupta | L26: 5
B27: Harry Potter | C27: Harry | D27: Potter | L27: 5
B28: Arnav Tripathi | C28: Arnav | D28: Tripathi | E28: 123 | F28: 1 | G28: 2 | H28: 3 | L28: 5
B29: Sushma Sharma | C29: Sushma | D29: Sharma | E29: 234 | F29: 2 | G29: 3 | H29: 4 | J29: Monday | L29: 5
B30: Jacob Peter | C30: Jacob | D30: Peter | E30: 345 | F30: 3 | G30: 4 | H30: 5 | J30: Tuesday | L30: 5
B31: Alisha Sinha | C31: Alisha | D31: Sinha | E31: 456 | F31: 4 | G31: 5 | H31: 6 | J31: Wednesday | L31: 5
B32: Alex Samson | C32: Alex | D32: Samson | E32: 567 | F32: 5 | G32: 6 | H32: 7 | J32: Thursday | L32: 5
B33: Rajul Kaur | C33: Rajul | D33: Kaur | E33: 678 | F33: 6 | G33: 7 | H33: 8 | J33: Friday | L33: 5
B34: Rocky Pattinson | C34: Rocky | D34: Pattinson | E34: 789 | F34: 7 | G34: 8 | H34: 9 | J34: Saturday | L34: 5
B35: Harry Potter | C35: Harry | D35: Potter | E35: 890 | F35: 8 | G35: 9 | H35: 0 | J35: Sunday | L35: 5
B36: Arnav Tripathi | C36: Arnav | D36: Tripathi | J36: Monday | L36: 5
B37: Sushma Sharma | C37: Sushma | D37: Sharma | J37: Tuesday | L37: 5
B38: Jacob Peter | C38: Jacob | D38: Peter | J38: Wednesday | L38: 5
B39: Alisha Sinha | C39: Alisha | D39: Sinha | J39: Thursday | L39: 5
E40: skfdhsnkf | L40: 5
E41: skfdhsnkf | L41: 5
...

Sheet Copying formulas
C2: Items | D2: Price | F2: Items | G2: Price
C3: Beard trimmer | D3: 4000 | F3: Jackets | G3: 6000 | J3: 1
C4: Hair dryer | D4: 9000 | F4: Earbuds | G4: 35700 | J4: 2
C5: Deodarant | D5: 8000 | F5: Bass Headphones | G5: 32640 | J5: 3
C6: Shaving cream | D6: 8000 | F6: Wrist watch | G6: 48960 | J6: 4
C7: Smartwatch | D7: 10000 | F7: Mobile | G7: 42840 | J7: 5
C8: Footwear | D8: 12000 | F8: Mobile | G8: 35700 | J8: =SUM(G3:G8) -> 201840
C9: TOTAL | D9: XSUM(D3:D8) | F9: TOTAL | G9: =SUM(G3:G8) -> 201840
C10: AVERAGE | D10: XAVERAGE(D3:D8) | F10: AVERAGE | G10: =AVERAGE(G3:G8) -> 33640
C11: MIN | D11: XMIN(D3:D8) | F11: MIN | G11: =MIN(G3:G8) -> 6000 | I11: =SUM(G3:G8) -> 201840
C13: Earbuds | D13: 35700 | F13: Hair dryer | G13: 9000 | J13: =SUM(G3:G8) -> 201840
C14: Bass Headphones | D14: 32640 | F14: Deodarant | G14: 8000 | J14: =AVERAGE(G3:G8) -> 33640
C15: Wrist watch | D15: 48960 | F15: Shaving cream | G15: 8000 | J15: =MIN(D3:D8) -> 4000
C16: Mobile | D16: 42840 | F16: Smartwatch | G16: 10000
C17: Beard trimmer | D17: 4000 | F17: Mobile | G17: 35700 | I17: =SUM(D3:D8) -> 51000
C18: TOTAL | D18: =SUM(D12:D17) -> 164140 | F18: TOTAL | G18: =SUM(G12:G17) -> 70700 | I18: =AVERAGE(D3:D8) -> 8500
C19: AVERAGE | D19: =AVERAGE(D12:D17) -> 32828 | F19: AVERAGE | G19: =AVERAGE(G12:G17) -> 14140 | I19: =MIN(D3:D8) -> 4000
C20: MIN | D20: =MIN(D12:D17) -> 4000 | F20: MIN | G20: =MIN(G12:G17) -> 8000
D24: Items | E24: Selling Price (Revenue) | F24: Cost Price (Expenses) | G24: Profit | H24: Profit %age
D25: Jackets | E25: 9000 | F25: 1000 | G25: =IMSUB(E25,F25) -> 8000 | H25: =G25/F25 -> 8
D26: Earbuds | E26: 8000 | F26: 2000 | G26: =IMSUB(E26,F26) -> 6000 | H26: =G26/F26 -> 3
D27: Bass Headphones | E27: 8000 | F27: 4000 | G27: =IMSUB(E27,F27) -> 4000 | H27: =G27/F27 -> 1
D28: Wrist watch | E28: 10000 | F28: 3000 | G28: =IMSUB(E28,F28) -> 7000 | H28: =G28/F28 -> 2.3333333
D29: Mobile | E29: 35700 | F29: 10000 | G29: =IMSUB(E29,F29) -> 25700 | H29: =G29/F29 -> 2.57
D30: TOTAL | E30: =SUM(E25:E29) -> 70700 | F30: =SUM(F25:F29) -> 20000 | G30: =IMSUM(G25:G29) -> 50700
D31: AVERAGE | E31: =AVERAGE(E25:E29) -> 14140 | F31: =AVERAGE(F25:F29) -> 4000
D32: MIN | E32: =MIN(E25:E29) -> 8000 | F32: =MIN(F25:F29) -> 1000

Sheet SUBTOTAL
B2: Date | C2: Region | D2: Items | E2: Price
B3: 36530 | C3: East | D3: Smartwatch | E3: 10000
B4: 36531 | C4: East | D4: Footwear | E4: 12000
B5: 36542 | C5: East | D5: Mobile | E5: 35700
B6: 36535 | C6: East | D6: Mobile | E6: 42840
C7: East Total | E7: =SUBTOTAL(9,E3:E6) -> 100540
B8: 36526 | C8: North | D8: Beard trimmer | E8: 4000
B9: 36528 | C9: North | D9: Deodarant | E9: 8000
B10: 36544 | C10: North | D10: Deodarant | E10: 8000
B11: 36545 | C11: North | D11: Shaving cream | E11: 8000
B12: 36533 | C12: North | D12: Bass Headphones | E12: 32640
B13: 36541 | C13: North | D13: Mobile | E13: 42840
B14: 36534 | C14: North | D14: Wrist watch | E14: 48960
C15: North Total | E15: =SUBTOTAL(9,E8:E14) -> 152440
B16: 36537 | C16: South | D16: Jackets | E16: 6000
B17: 36546 | C17: South | D17: Smartwatch | E17: 10000
B18: 36539 | C18: South | D18: Bass Headphones | E18: 32640
B19: 36538 | C19: South | D19: Earbuds | E19: 35700
B20: 36540 | C20: South | D20: Wrist watch | E20: 48960
C21: South Total | E21: =SUBTOTAL(9,E16:E20) -> 133300
B22: 36536 | C22: West | D22: Beard trimmer | E22: 4000
B23: 36529 | C23: West | D23: Shaving cream | E23: 8000
B24: 36527 | C24: West | D24: Hair dryer | E24: 9000
B25: 36543 | C25: West | D25: Hair dryer | E25: 9000
B26: 36532 | C26: West | D26: Earbuds | E26: 35700
B27: 36547 | C27: West | D27: Mobile | E27: 35700
C28: West Total | E28: =SUBTOTAL(9,E22:E27) -> 101400
B29: TOTAL | E29: =SUM(E3:E27) -> 873960
C30: Grand Total | E30: =SUBTOTAL(9,E3:E29) -> 1361640
B36: Date | C36: Region | D36: Items | E36: Price
B37: 36531 | C37: East | D37: Footwear | E37: 12000
B38: 36542 | C38: East | D38: Mobile | E38: 35700
B39: 36535 | C39: East | D39: Mobile | E39: 42840
B40: 36530 | C40: East | D40: Smartwatch | E40: 10000
B42: 36533 | C42: North | D42: Bass Headphones | E42: 32640
B43: 36526 | C43: North | D43: Beard trimmer | E43: 4000
B44: 36528 | C44: North | D44: Deodarant | E44: 8000
B45: 36544 | C45: North | D45: Deodarant | E45: 8000
B46: 36541 | C46: North | D46: Mobile | E46: 42840
B47: 36545 | C47: North | D47: Shaving cream | E47: 8000
...

Sheet ROUND FUNCTIONS
B2: FUNCTIONS / NUMBERS | C2: 163.4 | D2: 123.7 | E2: 133.68 | F2: 55.77 | G2: 67.345 | H2: 89.123 | I2: 12.4843 | J2: 25.7654
B3: ROUND (upto 0 decimal place) | C3: =ROUND(C2,0) -> 163 | D3: =ROUND(D2,0) -> 124 | E3: =ROUND(E2,0) -> 134 | F3: =ROUND(F2,0) -> 56 | G3: =ROUND(G2,0) -> 67 | H3: =ROUND(H2,0) -> 89 | I3: =ROUND(I2,0) -> 12 | J3: =ROUND(J2,0) -> 26
B4: ROUND (upto 1 decimal place) | C4: =ROUND(C2,1) -> 163.4 | D4: =ROUND(D2,1) -> 123.7 | E4: =ROUND(E2,1) -> 133.7 | F4: =ROUND(F2,1) -> 55.8 | G4: =ROUND(G2,1) -> 67.3 | H4: =ROUND(H2,1) -> 89.1 | I4: =ROUND(I2,1) -> 12.5 | J4: =ROUND(J2,1) -> 25.8
B5: ROUND (upto 2 decimal place) | C5: =ROUND(C2,2) -> 163.4 | D5: =ROUND(D2,2) -> 123.7 | E5: =ROUND(E2,2) -> 133.68 | F5: =ROUND(F2,2) -> 55.77 | G5: =ROUND(G2,2) -> 67.35 | H5: =ROUND(H2,2) -> 89.12 | I5: =ROUND(I2,2) -> 12.48 | J5: =ROUND(J2,2) -> 25.77
B6: ROUND (upto 3 decimal place) | C6: =ROUND(C2,3) -> 163.4 | D6: =ROUND(D2,3) -> 123.7 | E6: =ROUND(E2,3) -> 133.68 | F6: =ROUND(F2,3) -> 55.77 | G6: =ROUND(G2,3) -> 67.345 | H6: =ROUND(H2,3) -> 89.123 | I6: =ROUND(I2,3) -> 12.484 | J6: =ROUND(J2,3) -> 25.765
B8: ROUNDUP (upto 0 decimal place) | C8: =ROUNDUP(C2,0) -> 164 | D8: =ROUNDUP(D2,0) -> 124 | E8: =ROUNDUP(E2,0) -> 134 | F8: =ROUNDUP(F2,0) -> 56 | G8: =ROUNDUP(G2,0) -> 68 | H8: =ROUNDUP(H2,0) -> 90 | I8: =ROUNDUP(I2,0) -> 13 | J8: =ROUNDUP(J2,0) -> 26
B9: ROUNDUP (upto 1 decimal place) | C9: =ROUNDUP(C2,1) -> 163.4 | D9: =ROUNDUP(D2,1) -> 123.7 | E9: =ROUNDUP(E2,1) -> 133.7 | F9: =ROUNDUP(F2,1) -> 55.8 | G9: =ROUNDUP(G2,1) -> 67.4 | H9: =ROUNDUP(H2,1) -> 89.2 | I9: =ROUNDUP(I2,1) -> 12.5 | J9: =ROUNDUP(J2,1) -> 25.8
B10: ROUNDUP (upto 2 decimal place) | C10: =ROUNDUP(C2,2) -> 163.4 | D10: =ROUNDUP(D2,2) -> 123.7 | E10: =ROUNDUP(E2,2) -> 133.68 | F10: =ROUNDUP(F2,2) -> 55.77 | G10: =ROUNDUP(G2,2) -> 67.35 | H10: =ROUNDUP(H2,2) -> 89.13 | I10: =ROUNDUP(I2,2) -> 12.49 | J10: =ROUNDUP(J2,2) -> 25.77
B11: ROUNDUP (upto 3 decimal place) | C11: =ROUNDUP(C2,3) -> 163.4 | D11: =ROUNDUP(D2,3) -> 123.7 | E11: =ROUNDUP(E2,3) -> 133.68 | F11: =ROUNDUP(F2,3) -> 55.77 | G11: =ROUNDUP(G2,3) -> 67.345 | H11: =ROUNDUP(H2,3) -> 89.123 | I11: =ROUNDUP(I2,3) -> 12.485 | J11: =ROUNDUP(J2,3) -> 25.766
B13: ROUNDDOWN (upto 0 decimal place) | C13: =ROUNDDOWN(C2,0) -> 163 | D13: =ROUNDDOWN(D2,0) -> 123 | E13: =ROUNDDOWN(E2,0) -> 133 | F13: =ROUNDDOWN(F2,0) -> 55 | G13: =ROUNDDOWN(G2,0) -> 67 | H13: =ROUNDDOWN(H2,0) -> 89 | I13: =ROUNDDOWN(I2,0) -> 12 | J13: =ROUNDDOWN(J2,0) -> 25
B14: ROUNDDOWN(upto 1 decimal place) | C14: =ROUNDDOWN(C2,1) -> 163.4 | D14: =ROUNDDOWN(D2,1) -> 123.7 | E14: =ROUNDDOWN(E2,1) -> 133.6 | F14: =ROUNDDOWN(F2,1) -> 55.7 | G14: =ROUNDDOWN(G2,1) -> 67.3 | H14: =ROUNDDOWN(H2,1) -> 89.1 | I14: =ROUNDDOWN(I2,1) -> 12.4 | J14: =ROUNDDOWN(J2,1) -> 25.7
B15: ROUNDDOWN(upto 2 decimal place) | C15: =ROUNDDOWN(C2,2) -> 163.4 | D15: =ROUNDDOWN(D2,2) -> 123.7 | E15: =ROUNDDOWN(E2,2) -> 133.68 | F15: =ROUNDDOWN(F2,2) -> 55.77 | G15: =ROUNDDOWN(G2,2) -> 67.34 | H15: =ROUNDDOWN(H2,2) -> 89.12 | I15: =ROUNDDOWN(I2,2) -> 12.48 | J15: =ROUNDDOWN(J2,2) -> 25.76
B16: ROUNDDOWN (upto 3 decimal place) | C16: =ROUNDDOWN(C2,3) -> 163.4 | D16: =ROUNDDOWN(D2,3) -> 123.7 | E16: =ROUNDDOWN(E2,3) -> 133.68 | F16: =ROUNDDOWN(F2,3) -> 55.77 | G16: =ROUNDDOWN(G2,3) -> 67.345 | H16: =ROUNDDOWN(H2,3) -> 89.123 | I16: =ROUNDDOWN(I2,3) -> 12.484 | J16: =ROUNDDOWN(J2,3) -> 25.765
B18: MROUND (multiple of 10) | C18: =MROUND(C2,10) -> 160 | D18: =MROUND(D2,10) -> 120 | E18: =MROUND(E2,10) -> 130 | F18: =MROUND(F2,10) -> 60 | G18: =MROUND(G2,10) -> 70 | H18: =MROUND(H2,10) -> 90 | I18: =MROUND(I2,10) -> 10 | J18: =MROUND(J2,10) -> 30
B19: MROUND (multiple of 7) | C19: =MROUND(C2,7) -> 161 | D19: =MROUND(D2,7) -> 126 | E19: =MROUND(E2,7) -> 133 | F19: =MROUND(F2,7) -> 56 | G19: =MROUND(G2,7) -> 70 | H19: =MROUND(H2,7) -> 91 | I19: =MROUND(I2,7) -> 14 | J19: =MROUND(J2,7) -> 28
B20: MROUND (multiple of 3) | C20: =MROUND(C2,3) -> 162 | D20: =MROUND(D2,3) -> 123 | E20: =MROUND(E2,3) -> 135 | F20: =MROUND(F2,3) -> 57 | G20: =MROUND(G2,3) -> 66 | H20: =MROUND(H2,3) -> 90 | I20: =MROUND(I2,3) -> 12 | J20: =MROUND(J2,3) -> 27
B21: MROUND (multiple of 2) | C21: =MROUND(C2,2) -> 164 | D21: =MROUND(D2,2) -> 124 | E21: =MROUND(E2,2) -> 134 | F21: =MROUND(F2,2) -> 56 | G21: =MROUND(G2,2) -> 68 | H21: =MROUND(H2,2) -> 90 | I21: =MROUND(I2,2) -> 12 | J21: =MROUND(J2,2) -> 26

Sheet Text functions
B3: NAMES | C3: UPPER | D3: LOWER | E3: PROPER | F3: LEFT | G3: RIGHT | H3: MID
B4: Ananya Pandey | C4: =UPPER(B4) -> ANANYA PANDEY | D4: =LOWER(B4) -> ananya pandey | E4: =PROPER(B4) -> Ananya Pandey | F4: =LEFT(B4, 5) -> Anany | G4: =RIGHT(B4, 5) -> andey | H4: =MID(B4, 2, 3) -> nan
B5: Arohi Sharma | C5: =UPPER(B5) -> AROHI SHARMA | D5: =LOWER(B5) -> arohi sharma | E5: =PROPER(B5) -> Arohi Sharma | F5: =LEFT(B5, 8) -> Arohi Sh | G5: =RIGHT(B5, 8) -> i Sharma | H5: =MID(B5, 3, 5) -> ohi S
B6: Mohandas Karamchand Gandhi | C6: =UPPER(B6) -> MOHANDAS KARAMCHAND GANDHI | D6: =LOWER(B6) -> mohandas karamchand gandhi | E6: =PROPER(B6) -> Mohandas Karamchand Gandhi | F6: =LEFT(B6, 8) -> Mohandas | G6: =RIGHT(B6, 8) -> d Gandhi | H6: =MID(B6, 3, 5) -> handa
B7: Milind Kumar Kalra | C7: =UPPER(B7) -> MILIND KUMAR KALRA | D7: =LOWER(B7) -> milind kumar kalra | E7: =PROPER(B7) -> Milind Kumar Kalra | F7: =LEFT(B7, 8) -> Milind K | G7: =RIGHT(B7, 8) -> ar Kalra | H7: =MID(B7, 3, 5) -> lind
B8: Anshu Poonawala | C8: =UPPER(B8) -> ANSHU POONAWALA | D8: =LOWER(B8) -> anshu poonawala | E8: =PROPER(B8) -> Anshu Poonawala | F8: =LEFT(B8, 8) -> Anshu Po | G8: =RIGHT(B8, 8) -> oonawala | H8: =MID(B8, 3, 5) -> shu P
B9: Rahul Singh Sharma | C9: =UPPER(B9) -> RAHUL SINGH SHARMA | D9: =LOWER(B9) -> rahul singh sharma | E9: =PROPER(B9) -> Rahul Singh Sharma | F9: =LEFT(B9, 8) -> Rahul Si | G9: =RIGHT(B9, 8) -> h Sharma | H9: =MID(B9, 3, 5) -> hul S
B10: Neil Armstrong | C10: =UPPER(B10) -> NEIL ARMSTRONG | D10: =LOWER(B10) -> neil armstrong | E10: =PROPER(B10) -> Neil Armstrong | F10: =LEFT(B10, 8) -> Neil Arm | G10: =RIGHT(B10, 8) -> rmstrong | H10: =MID(B10, 3, 5) -> il Ar
B11: Avnish Agrawal | C11: =UPPER(B11) -> AVNISH AGRAWAL | D11: =LOWER(B11) -> avnish agrawal | E11: =PROPER(B11) -> Avnish Agrawal | F11: =LEFT(B11, 8) -> Avnish A | G11: =RIGHT(B11, 8) -> Agrawal | H11: =MID(B11, 3, 5) -> nish
B12: Shashank Khan | C12: =UPPER(B12) -> SHASHANK KHAN | D12: =LOWER(B12) -> shashank khan | E12: =PROPER(B12) -> Shashank Khan | F12: =LEFT(B12, 8) -> Shashank | G12: =RIGHT(B12, 8) -> ank Khan | H12: =MID(B12, 3, 5) -> ashan
B16: NAMES | C16: LENGTH | D16: TRIM | E16: LENGTH | F16: FIND | G16: SEARCH
B17: Ananya Pandey | C17: =LEN(B17) -> 17 | D17: =TRIM(B17) -> Ananya Pandey | E17: =LEN(D17) -> 13 | F17: =FIND("y", D17, 7) -> 13 | G17: =SEARCH("y", D17, 7) -> 13
B18: Arohi Sharma | C18: =LEN(B18) -> 19 | D18: =TRIM(B18) -> Arohi Sharma | E18: =LEN(D18) -> 12 | F18: =FIND("r", D18, 5) -> 10 | G18: =SEARCH("r", D18, 5) -> 10
B19: Mohandas Karamchand G andhi | C19: =LEN(B19) -> 33 | D19: =TRIM(B19) -> Mohandas Karamchand G andhi | E19: =LEN(D19) -> 27 | F19: =FIND("M", D19) -> 1 | G19: =SEARCH("M", D19) -> 1
B20: Milind Kalra | C20: =LEN(B20) -> 27 | D20: =TRIM(B20) -> Milind Kalra | E20: =LEN(D20) -> 12 | F20: =FIND("l", D20) -> 3 | G20: =SEARCH("l",D20) -> 3
B21: Anshu Poonawala | C21: =LEN(B21) -> 30 | D21: =TRIM(B21) -> Anshu Poonawala | E21: =LEN(D21) -> 15 | F21: =FIND("o", D21) -> 8 | G21: =SEARCH("o", D21) -> 8
B22: Rahul Singh Sharma | C22: =LEN(B22) -> 24 | D22: =TRIM(B22) -> Rahul Singh Sharma | E22: =LEN(D22) -> 18 | F22: =FIND("g", D22) -> 10 | G22: =SEARCH("g", E22) -> #VALUE!
B23: Neil Armstrong | C23: =LEN(B23) -> 18 | D23: =TRIM(B23) -> Neil Armstrong | E23: =LEN(D23) -> 14 | F23: =FIND("g", D23) -> 14 | G23: =SEARCH("g", E23) -> #VALUE!
B24: Avnish Agrawal | C24: =LEN(B24) -> 14 | D24: =TRIM(B24) -> Avnish Agrawal | E24: =LEN(D24) -> 14 | F24: =FIND("g", D24) -> 9 | G24: =SEARCH("g", E24) -> #VALUE!
B25: Shashank Khan | C25: =LEN(B25) -> 18 | D25: =TRIM(B25) -> Shashank Khan | E25: =LEN(D25) -> 13 | F25: =FIND("K", D25) -> 10 | G25: =SEARCH("K", E25) -> #VALUE!
C28: NAMES | D28: SUBSTITUTE | E28: REPLACE
C29: Ananya Pandey | D29: =SUBSTITUTE(C29, "an", "Po") -> AnPoya PPodey | E29: =REPLACE(C29, 1, 5, "Po") -> Poa Pandey
C30: Arohi Sharma | D30: =SUBSTITUTE(C30, "rohi", "tul") -> Atul Sharma | E30: =REPLACE(C30, 1, 5, "Tul") -> Tul Sharma
C31: Mohandas Karamchand Gandhi | D31: =SUBSTITUTE(C31, "das", "tul") -> Mohantul Karamchand Gandhi | E31: =REPLACE(C31, 1, 5, "Tul") -> Tuldas Karamchand Gandhi
C32: Milind Kumar Kalra | D32: =SUBSTITUTE(C32, "lind", "tul") -> Mitul Kumar Kalra | E32: =REPLACE(C32, 1, 5, "Tul") -> Tuld Kumar Kalra
C33: Anshu Poonawala | D33: =SUBSTITUTE(C33, "oona", "tul") -> Anshu Ptulwala | E33: =REPLACE(C33, 1, 5, "Tul") -> Tul Poonawala
C34: Rahul Singh Sharma | D34: =SUBSTITUTE(C34, "Rahul", "tul") -> tul Singh Sharma | E34: =REPLACE(C34, 1, 5, "Tul") -> Tul Singh Sharma
C35: Neil Armstrong | D35: =SUBSTITUTE(C35, "strong", "tul") -> Neil Armtul | E35: =REPLACE(C35, 1, 5, "Tul") -> TulArmstrong
C36: Avnish Agrawal | D36: =SUBSTITUTE(C36, "wal", "tul") -> Avnish Agratul | E36: =REPLACE(C36, 1, 5, "Tul") -> Tulh Agrawal
C37: Shashank Khan | D37: =SUBSTITUTE(C37, "ank", "tul") -> Shashtul Khan | E37: =REPLACE(C37, 1, 5, "Tul") -> Tulank Khan
C39: You don't always know what you don't know. | D39: =SUBSTITUTE(C39, "know", "have", 1) -> You don't always have what you don't know. | E39: =REPLACE(C39, 8, 5, "have") -> You donhaveways know what you don't know.
D40: =SUBSTITUTE(C39, "know", "have", 2) -> You don't always know what you don't have. | E40: =REPLACE("know", 2, 2, "have") -> khavew
G41: CONCATENATE
E42: abc | F42: xyz | G42: =_xlfn.CONCAT(E42, " ", F42) -> abc xyz
E43: def | F43: uvw | G43: =_xlfn.CONCAT(E43, " & ", F43) -> def & uvw
E44: 123 | F44: 456 | G44: =_xlfn.CONCAT(E44, " - ", F44) -> 123 - 456
E45: 567 | F45: 789 | G45: =_xlfn.CONCAT(E45, " * ", F45) -> 567 * 789
E46: 567 | F46: xyz | G46: =_xlfn.CONCAT(E46, " @ ", F46) -> 567 @ xyz

Sheet Basic formatting
B2: Date | C2: Region | D2: Items | E2: Price
B3: 37262 | C3: East | D3: Footwear | E3: 12002
B4: 37273 | C4: East | D4: Mobile | E4: 35700 | G4: 0.92013889 | H4: 37257
B5: 37266 | C5: East | D5: Mobile | E5: 42840
B6: 37261 | C6: East | D6: Smartwatch | E6: 10000 | H6: D | I6: 1 | J6: 12
B7: 37262 | C7: East | D7: Smartwatch | E7: 30000 | H7: M | I7: 3 | J7: 12
B8: 37264 | C8: North | D8: Bass Headphones | E8: 32640 | H8: DD | I8: 01
B9: 37257 | C9: North | D9: Beard trimmer | E9: 4000 | H9: MM | I9: 02
B10: 37259 | C10: North | D10: Deodarant | E10: 8000 | H10: DDD | I10: Wed
B11: 37275 | C11: North | D11: Deodarant | E11: 8000 | H11: MMM | I11: Feb
B12: 37272 | C12: North | D12: Mobile | E12: 42840 | H12: DDDD | I12: Wednesday
B13: 37276 | C13: North | D13: Shaving cream | E13: 8000 | H13: MMMM | I13: February
B14: 37265 | C14: North | D14: Wrist watch | E14: 48960 | H14: YY | I14: 20
B15: 37270 | C15: South | D15: Bass Headphones | E15: 32640 | H15: YYYY | I15: 2020
B16: 37271 | C16: South | D16: Bass Headphones | E16: 42002
B17: 37269 | C17: South | D17: Earbuds | E17: 35700
B18: 37268 | C18: South | D18: Jackets | E18: 6000 | G18: 37262 | H18: dd/mm/yy
B19: 37277 | C19: South | D19: Smartwatch | E19: 10000 | G19: 37273 | H19: mm/dd/yy
B20: 37271 | C20: South | D20: Wrist watch | E20: 48960 | G20: 37266 | H20: dddd/mm/yy
B21: 37267 | C21: West | D21: Beard trimmer | E21: 4000 | G21: 37261 | H21: dddd/mmmm/yyyy
B22: 37263 | C22: West | D22: Earbuds | E22: 35700 | G22: 37262 | H22: dd-mm-yyyy-dddd
B23: 37258 | C23: West | D23: Hair dryer | E23: 7000 | G23: 37264
B24: 37274 | C24: West | D24: Hair dryer | E24: 9000 | G24: 37257 | H24: 37262
B25: 37278 | C25: West | D25: Mobile | E25: 35700 | G25: 37250
B26: 37260 | C26: West | D26: Shaving cream | E26: 8000 | G26: 37243
G27: 37236
G28: 37229

Sheet Logical operators (test)
B2: Date | C2: Region | D2: Items | E2: Price | J2: Comparative / Logical operators
B3: 36531 | C3: East | D3: Footwear | E3: 12000 | J3: =
B4: 36542 | C4: East | D4: Mobile | E4: 35700 | J4: >
B5: 36535 | C5: East | D5: Mobile | E5: 42840 | J5: <
B6: 36530 | C6: East | D6: Smartwatch | E6: 10000 | F6: =E4>E11 -> FALSE | G6: =D3>D9 -> TRUE | J6: >=
B7: 36533 | C7: North | D7: Bass Headphones | E7: 32640 | F7: =E4<E11 -> TRUE | G7: =D9<D11 -> TRUE | J7: <=
B8: 36526 | C8: North | D8: Beard trimmer | E8: 4000 | F8: =E10=E9 -> TRUE | G8: =D8>=D13 -> FALSE | J8: <>
B9: 36528 | C9: North | D9: Deodarant | E9: 8000 | F9: =E4>=E11 -> FALSE | G9: =D16<=D15 -> FALSE
B10: 36544 | C10: North | D10: Deodarant | E10: 8000 | F10: =E4<=E11 -> TRUE | G10: =D9=D4 -> FALSE
B11: 36541 | C11: North | D11: Mobile | E11: 42840 | F11: =E9<>E12 -> FALSE | G11: =D9=D10 -> TRUE
B12: 36545 | C12: North | D12: Shaving cream | E12: 8000 | F12: =E7<>E13 -> TRUE | G12: =D12<>D14 -> TRUE
B13: 36534 | C13: North | D13: Wrist watch | E13: 48960
B14: 36539 | C14: South | D14: Bass Headphones | E14: 32640
B15: 36538 | C15: South | D15: Earbuds | E15: 35700
B16: 36537 | C16: South | D16: Jackets | E16: 6000
B17: 36546 | C17: South | D17: Smartwatch | E17: 10000
B18: 36540 | C18: South | D18: Wrist watch | E18: 48960
B19: 36536 | C19: West | D19: Beard trimmer | E19: 4000
B20: 36532 | C20: West | D20: Earbuds | E20: 35700
B21: 36527 | C21: West | D21: Hair dryer | E21: 9000
B22: 36543 | C22: West | D22: Hair dryer | E22: 9000
B23: 36547 | C23: West | D23: Mobile | E23: 35700
B24: 36529 | C24: West | D24: Shaving cream | E24: 8000

Sheet How to use IF functions
C3: Date | D3: Region | E3: Items | F3: Price
C4: 36531 | D4: East | E4: Footwear | F4: 12000 | I4: No
C5: 36542 | D5: East | E5: Mobile | F5: 35700 | I5: Yes
C6: 36535 | D6: East | E6: Mobile | F6: 42840 | I6: Yes, No
C7: 36530 | D7: East | E7: Smartwatch | F7: 10000 | I7: 10, 20
C8: 36533 | D8: North | E8: Bass Headphones | F8: 32640 | I8: YES, NO
C9: 36526 | D9: North | E9: Beard trimmer | F9: 4000 | I9: Expensive, Inexpensive
C10: 36528 | D10: North | E10: Deodarant | F10: 8000
C11: 36544 | D11: North | E11: Deodarant | F11: 8000 | H11: =IF(F4>F5, "Yes", "No") -> No
C12: 36541 | D12: North | E12: Mobile | F12: 42840 | H12: =IF(F4<F5, "Yes", "No") -> Yes
C13: 36545 | D13: North | E13: Shaving cream | F13: 8000 | H13: =IF(F8>F14, 10, 20) -> 20
C14: 36534 | D14: North | E14: Wrist watch | F14: 48960 | H14: =IF(F9<F15, 10, 20) -> 10
C15: 36539 | D15: South | E15: Bass Headphones | F15: 32640 | H15: =IF(F7=F18, "YES", "NO") -> YES
C16: 36538 | D16: South | E16: Earbuds | F16: 35700 | H16: =IF(F18=F7, UPPER(I5), UPPER(I4)) -> YES
C17: 36537 | D17: South | E17: Jackets | F17: 6000 | H17: =IF(F21<>F19, "Expensive", "Inexpensive") -> Expensive
C18: 36546 | D18: South | E18: Smartwatch | F18: 10000 | H18: =IF(F21>F19, "Expensive", "Inexpensive") -> Inexpensive
C19: 36540 | D19: South | E19: Wrist watch | F19: 48960
C20: 36536 | D20: West | E20: Beard trimmer | F20: 4000
C21: 36532 | D21: West | E21: Earbuds | F21: 35700
C22: 36527 | D22: West | E22: Hair dryer | F22: 9000
C23: 36543 | D23: West | E23: Hair dryer | F23: 9000
C24: 36547 | D24: West | E24: Mobile | F24: 35700
C25: 36529 | D25: West | E25: Shaving cream | F25: 8000

Sheet Absolute Relative cell referenc
B3: Items | C3: Selling Price (Revenue) | D3: Cost Price (Expenses) | E3: Profit (SP - CP) | F3: Profit (SP - CP (10000)) | G3: Profit/50
B4: Jackets | C4: 20000 | D4: 1000 | E4: =IMSUB(C4,D4) -> 19000 | F4: =C4-$E$13 -> 10000 | G4: =F4/$E$12 -> 200
B5: Earbuds | C5: 11000 | D5: 2000 | E5: =IMSUB(C5,D5) -> 9000 | F5: =C5-$E$13 -> 1000 | G5: =F5/$E$12 -> 20
B6: Bass Headphones | C6: 11000 | D6: 4000 | E6: =IMSUB(C6,D6) -> 7000 | F6: =C6-$E$13 -> 1000 | G6: =F6/$E$12 -> 20
B7: Wrist watch | C7: 10000 | D7: 3000 | E7: =IMSUB(C7,D7) -> 7000 | F7: =C7-$E$13 -> 0 | G7: =F7/$E$12 -> 0
B8: Mobile | C8: 35000 | D8: 10000 | E8: =IMSUB(C8,D8) -> 25000 | F8: =C8-$E$13 -> 25000 | G8: =F8/$E$12 -> 500
B9: TOTAL | C9: =SUM(C4:C8) -> 87000 | D9: =SUM(D4:D8) -> 20000
C12: Divide by | E12: 50
C13: Cost Price (Expense) | E13: 10000

Sheet If functions 
C2: Date | D2: Region | E2: Items | F2: Price
C3: 36531 | D3: East | E3: Footwear | F3: 12000 | H3: SUMIF | I3: AVERAGEIF | J3: NESTEDIF
C4: 36542 | D4: East | E4: Mobile | F4: 35700 | H4: =SUMIF(D3:D24, "East", F3:F24) -> 100540 | I4: =AVERAGEIF(D3:D24, "west", F3:F24) -> 11450 | J4: =IF(F3>F11, "YES", IF(F14<F15, "True")) -> True
C5: 36535 | D5: East | E5: Mobile | F5: 42840 | J5: =IF(F8=F10, "Correct", IF(F20>F6, "Perfect", IF(F13>F17, "YES"))) -> YES
C6: 36530 | D6: East | E6: Smartwatch | F6: 10000 | H6: =SUMIF(D3:D24, "South", F3:F24) -> 133300 | I6: =AVERAGEIF(D3:D24, "north", F3:F24) -> 21777.143
C7: 36533 | D7: North | E7: Bass Headphones | F7: 32640 | J7: =IF(F12<>F10, "NO", IF(F6<>F17, "no", IF(F14>F4, "OOOO", IF(F23<>F4, "YES")))) -> FALSE
C8: 36526 | D8: North | E8: Beard trimmer | F8: 4000 | H8: =SUMIF(E3:E24, "Deodarant", F3:F24) -> 16000 | I8: =AVERAGEIF(E3:E24, "wrist watch", F3:F24) -> 48960
C9: 36528 | D9: North | E9: Deodarant | F9: 8000
C10: 36544 | D10: North | E10: Deodarant | F10: 8000 | H10: =SUMIF(E3:E24, "beard trimmer", F3:F24) -> 8000 | I10: =AVERAGEIF(E3:E24, "Earbuds", F3:F24) -> 19350
C11: 36541 | D11: North | E11: Mobile | F11: 42840
C12: 36545 | D12: North | E12: Shaving cream | F12: 8000
C13: 36534 | D13: North | E13: Wrist watch | F13: 48960
C14: 36539 | D14: South | E14: Bass Headphones | F14: 32640
C15: 36538 | D15: South | E15: Earbuds | F15: 35700
C16: 36537 | D16: South | E16: Jackets | F16: 6000
C17: 36546 | D17: South | E17: Smartwatch | F17: 10000
C18: 36540 | D18: South | E18: Wrist watch | F18: 48960
C19: 36536 | D19: West | E19: Beard trimmer | F19: 4000
C20: 36532 | D20: West | E20: Earbuds | F20: 3000
C21: 36527 | D21: West | E21: Hair dryer | F21: 9000
C22: 36543 | D22: West | E22: Hair dryer | F22: 9000
... C24: 36529 | D24: West | E24: Shaving cream | F24: 8000

Sheet IFs Functions
B2: Date | C2: Region | D2: Items | E2: Price | H2: Region | I2: Items | J2: Price
B3: 36531 | C3: East | D3: Footwear | E3: 12000 | H3: South | I3: Smartwatch | J3: >20000
B4: 36542 | C4: East | D4: Mobile | E4: 35700 | H4: North | I4: Beard trimmer | J4: >40000
B5: 36535 | C5: East | D5: Mobile | E5: 42840 | H5: East | I5: Mobile | J5: <=30000
B6: 36536 | C6: East | D6: Mobile | E6: 50000
B7: 36530 | C7: East | D7: Smartwatch | E7: 10000
B8: 36531 | C8: East | D8: Smartwatch | E8: 30000
B9: 36533 | C9: North | D9: Bass Headphones | E9: 30640
B10: 36526 | C10: North | D10: Beard trimmer | E10: 4000 | G10: Sumifs | H10: Averageifs | I10: Minifs | J10: Maxifs
B11: 36528 | C11: North | D11: Deodarant | E11: 8000 | G11: =SUMIFS(E3:E28, C3:C28, "East", D3:D28, "Mobile") -> 128540 | H11: =AVERAGEIFS(E3:E28, C3:C28, "East", D3:D28, "Mobile") -> 42846.667 | I11: =_xlfn.MINIFS(E3:E28, C3:C28, "East", D3:D28, "Mobile") -> 35700 | J11: =_xlfn.MAXIFS(E3:E28, C3:C28, "East", D3:D28, "Mobile") -> 50000
B12: 36544 | C12: North | D12: Deodarant | E12: 10000
B13: 36541 | C13: North | D13: Mobile | E13: 42840 | G13: =SUMIFS(E3:E28, C3:C28, "South", D3:D28, "Bass headphones") -> 74640 | H13: =AVERAGEIFS(E3:E28, C3:C28, "North", D3:D28, "Deodarant") -> 9000 | I13: =_xlfn.MINIFS(E3:E28, C3:C28, "North", D3:D28, "Bass headphones") -> 30640 | J13: =_xlfn.MAXIFS(E3:E28, C3:C28, "West", D3:D28, "hair dryer", E3:E28, ">10000") -> 11000
B14: 36545 | C14: North | D14: Shaving cream | E14: 8000
B15: 36534 | C15: North | D15: Wrist watch | E15: 48960 | G15: =SUMIFS(E3:E28, C3:C28, "West", D3:D28, "Hair dryer", E3:E28, ">5000") -> 27000 | H15: =AVERAGEIFS(E3:E28, C3:C28, "West", D3:D28, "Hair dryer", E3:E28, ">5000") -> 9000 | I15: =_xlfn.MINIFS(E3:E28, C3:C28, "South", D3:D28, "Bass headphones", E3:E28, ">=30000") -> 32640
B16: 36539 | C16: South | D16: Bass Headphones | E16: 32640
B17: 36540 | C17: South | D17: Bass Headphones | E17: 42000
B18: 36538 | C18: South | D18: Earbuds | E18: 35700
B19: 36537 | C19: South | D19: Jackets | E19: 6000
B20: 36546 | C20: South | D20: Smartwatch | E20: 10000
B21: 36540 | C21: South | D21: Wrist watch | E21: 48960
B22: 36536 | C22: West | D22: Beard trimmer | E22: 4000
B23: 36532 | C23: West | D23: Earbuds | E23: 35700
B24: 36527 | C24: West | D24: Hair dryer | E24: 7000
B25: 36543 | C25: West | D25: Hair dryer | E25: 9000
B26: 36544 | C26: West | D26: Hair dryer | E26: 11000
B27: 36547 | C27: West | D27: Mobile | E27: 35700
B28: 36529 | C28: West | D28: Shaving cream | E28: 8000

Sheet Database functions
B1: Date | C1: Region | D1: Items | E1: Price | H1: Region | I1: Items | J1: Price
B2: 36533 | C2: East | D2: Bass Headphones | E2: 2000 | H2: South | I2: Bass Headphones | J2: >20000
B3: 36531 | C3: East | D3: Footwear | E3: 4000
B4: 36542 | C4: East | D4: Mobile | E4: 6000 | H4: Region | I4: Items | J4: Price
B5: 36535 | C5: East | D5: Mobile | E5: 8000 | H5: West | I5: Beard trimmer | J5: >40000
B6: 36530 | C6: East | D6: Smartwatch | E6: 10000
B7: 36531 | C7: East | D7: Smartwatch | E7: 12000 | H7: Items | I7: Region | J7: Price
B8: 36526 | C8: North | D8: Beard trimmer | E8: 14000 | H8: Mobile | I8: East | J8: >3000
B9: 36528 | C9: North | D9: Beard trimmer | E9: 16000
B10: 36530 | C10: North | D10: Beard trimmer | E10: 18000
B11: 36544 | C11: North | D11: Deodarant | E11: 18000
B12: 36545 | C12: North | D12: Shaving cream | E12: 20000 | G12: SUMIFS | H12: DSUM | I12: DAVERAGE | J12: DMIN | K12: DMAX
B13: 36534 | C13: North | D13: Wrist watch | E13: 22000 | G13: =SUMIFS(E2:E28, C2:C28, "South", D2:D28, "Bass headphones", E2:E28, ">20000") -> 70000 | H13: =DSUM(B1:E28, E1, H1:J2) -> 70000 | I13: =DAVERAGE(B1:E28, E1, H1:J2) -> 35000 | J13: =DMIN(B1:E28, E1, H1:J2) -> 30000 | K13: =DMAX(B1:E28, E1, H1:J2) -> 40000
B14: 36535 | C14: North | D14: Wrist watch | E14: 25000
B15: 36539 | C15: South | D15: Bass Headphones | E15: ABC | H15: =DSUM(B1:E28, E1, H4:J5) -> 107000 | I15: =DAVERAGE(B1:E28, E1, H4:J5) -> 53500 | J15: =DMIN(B1:E28, E1, H4:J5) -> 50000 | K15: =DMAX(B1:E28, E1, H4:J5) -> 57000
B16: 36540 | C16: South | D16: Bass Headphones | E16: 30000
B17: 36540 | C17: South | D17: Bass Headphones | E17: 40000 | H17: =DSUM(B1:E29, E1, H7:J8) -> 14000 | I17: =DAVERAGE(B1:E28, E1, H7:J8) -> 7000 | J17: =DMIN(B1:E28, E1, H7:J8) -> 6000 | K17: =DMAX(B1:E28, E1, H7:J8) -> 8000
B18: 36540 | C18: South | D18: Bass Headphones | E18: 15000
B19: 36538 | C19: South | D19: Earbuds | E19: 30000
B20: 36537 | C20: South | D20: Jackets | E20: 32000 | H20: DCOUNT | I20: DCOUNTA | J20: DPRODUCT
B21: 36538 | C21: South | D21: Jackets | E21: 34000 | H21: =DCOUNT(B1:E28, E1,H1:J2) -> 2 | I21: =DCOUNTA(B1:E28, E1, H1:I2) -> 4 | J21: =DPRODUCT(B1:E28, E1, H1:J2) -> 1200000000
B22: 36536 | C22: West | D22: Beard trimmer | E22: 36000
B23: 36537 | C23: West | D23: Beard trimmer | E23: XYZ | H23: =DCOUNT(B1:E28, E1, H4:I5) -> 3 | I23: =DCOUNTA(B1:E28, E1, H4:I5) -> 4 | J23: =DPRODUCT(B1:E28, E1, H4:J5) -> 2850000000
B24: 36537 | C24: West | D24: Beard trimmer | E24: 50000
B25: 36538 | C25: West | D25: Beard trimmer | E25: 57000 | H25: =DCOUNT(B1:E28, E1, H7:I8) -> 2 | I25: =DCOUNTA(B1:E28, E1, H7:I8) -> 2 | J25: =DPRODUCT(B1:E28, E1, H7:J8) -> 48000000
B26: 36532 | C26: West | D26: Earbuds | E26: 38000
B27: 36547 | C27: West | D27: Mobile | E27: 40000
B28: 36529 | C28: West | D28: Shaving cream | E28: 42000
C31: ARRAY
B32: Items | C32: Selling Price (Revenue) | D32: Cost Price (Expenses) | E32: Profit
B33: Jackets | C33: 9000 | D33: 1000
B34: Earbuds | C34: 8000 | D34: 2000
B35: Bass Headphones | C35: 8000 | D35: 4000
B36: Wrist watch | C36: 10000 | D36: 3000
B37: Mobile | C37: 35700 | D37: 10000
B38: Beard trimmer | C38: 15000 | D38: 18000
B39: Jackets | C39: 30000 | D39: 18000
B40: Shaving cream | C40: 32000 | D40: 20000
B41: Smartwatch | C41: 34000 | D41: 22000
B42: Footwear | C42: 36000 | D42: 25000
...

Sheet Logical functions
C2: AND, OR, NOT, XOR
B4: Names | C4: GK | D4: Math | E4: English | F4: Science
B5: Harish | C5: 30 | D5: 40 | E5: 49 | F5: 34
B6: Seeta | C6: 82 | D6: 29 | E6: 41 | F6: 56
B7: Aryan | C7: 22 | D7: 64 | E7: 30 | F7: 47 | G7: =IF(OR(C5>50,D5>50,E5>50,F5>50),"PASSED","FAILED") -> FAILED
B8: Sushant | C8: 75 | D8: 21 | E8: 78 | F8: 77 | G8: =IF(OR(C6>50,D6>50,E6>50,F6>50),"PASSED","FAILED") -> PASSED
B9: Mayara | C9: 39 | D9: 37 | E9: 45 | F9: 22 | G9: =IF(OR(C7>50,D7>50,E7>50,F7>50),"PASSED","FAILED") -> PASSED
B10: Neelam | C10: 39 | D10: 71 | E10: 28 | F10: 90 | G10: =IF(AND(C8>50,D8>50,E8>50,F8>50),"PASSED","FAILED") -> FAILED
B11: Uday | C11: 42 | D11: 38 | E11: 12 | F11: 40 | G11: =IF(OR(C9>50,D9>50,E9>50,F9>50),"PASSED","FAILED") -> FAILED
B12: Preetam | C12: 76 | D12: 35 | E12: 35 | F12: 27
B13: Preeti | C13: 39 | D13: 50 | E13: 66 | F13: 26
B14: TOTAL | C14: =SUM(C5:C13) -> 444 | D14: =SUM(D5:D13) -> 385 | E14: =SUM(E5:E13) -> 384 | F14: =SUM(F5:F13) -> 419
B17: OR | C17: TRUE | D17: FALSE | E17: TRUE
B18: AND | C18: TRUE | D18: TRUE | E18: TRUE
B19: AND | C19: FALSE | D19: TRUE | E19: FALSE
B20: XOR | C20: FALSE | D20: TRUE | E20: TRUE
B21: XOR | C21: TRUE | D21: FALSE | E21: TRUE
B22: XOR | C22: TRUE | D22: TRUE | E22: FALSE
A25: Names | B25: Logical Analysis (OR) | C25: Result | D25: Logical Analysis (AND) | E25: Result | F25: Logical Analysis (XOR)
A26: Harish | B26: =OR(C5>50, D5>50, E5>50, F5>50) -> FALSE | C26: =IF(B26=TRUE, "Passed", "Failed") -> Failed | D26: =AND(C5>50, D5>50, E5>50, F5>50) -> FALSE | E26: =IF(D26=TRUE, "Passed", "Failed") -> Failed | F26: =_xlfn.XOR(C5>50, D5>50, E5>50, F5>50) -> FALSE
A27: Seeta | B27: =OR(C6>50, D6>50, E6>50, F6>50) -> TRUE | C27: =IF(B27=TRUE, "Passed", "Failed") -> Passed | D27: =AND(C6>50, D6>50, E6>50, F6>50) -> FALSE | E27: =IF(D27=TRUE, "Passed", "Failed") -> Failed | F27: =_xlfn.XOR(C6>50, D6>50, E6>50, F6>50) -> FALSE
A28: Aryan | B28: =OR(C7>50, D7>50, E7>50, F7>50) -> TRUE | C28: =IF(B28=TRUE, "Passed", "Failed") -> Passed | D28: =AND(C7>50, D7>50, E7>50, F7>50) -> FALSE | E28: =IF(D28=TRUE, "Passed", "Failed") -> Failed | F28: =_xlfn.XOR(C7>50, D7>50, E7>50, F7>50) -> TRUE | G28: XOR result - TRUE, when the number of valid/correct inputs is odd. XOR result - FALSE, when the number of valid/correct inputs is even.
A29: Sushant | B29: =OR(C8>50, D8>50, E8>50, F8>50) -> TRUE | C29: =IF(B29=TRUE, "Passed", "Failed") -> Passed | D29: =AND(C8>50, D8>50, E8>50, F8>50) -> FALSE | E29: =IF(D29=TRUE, "Passed", "Failed") -> Failed | F29: =_xlfn.XOR(C8>50, D8>50, E8>50, F8>50) -> TRUE
A30: Mayara | B30: =OR(C9>50, D9>50, E9>50, F9>50) -> FALSE | C30: =IF(B30=TRUE, "Passed", "Failed") -> Failed | D30: =AND(C9>50, D9>50, E9>50, F9>50) -> FALSE | E30: =IF(D30=TRUE, "Passed", "Failed") -> Failed | F30: =_xlfn.XOR(C9>50, D9>50, E9>50, F9>50) -> FALSE
A31: Neelam | B31: =OR(C10>50, D10>50, E10>50, F10>50) -> TRUE | C31: =IF(B31=TRUE, "Passed", "Failed") -> Passed | D31: =AND(C10>50, D10>50, E10>50, F10>50) -> FALSE | E31: =IF(D31=TRUE, "Passed", "Failed") -> Failed | F31: =_xlfn.XOR(C10>50, D10>50, E10>50, F10>50) -> FALSE
A32: Uday | B32: =OR(C11>50, D11>50, E11>50, F11>50) -> FALSE | C32: =IF(B32=TRUE, "Passed", "Failed") -> Failed | D32: =AND(C11>50, D11>50, E11>50, F11>50) -> FALSE | E32: =IF(D32=TRUE, "Passed", "Failed") -> Failed | F32: =_xlfn.XOR(C11>50, D11>50, E11>50, F11>50) -> FALSE
A33: Preetam | B33: =OR(C12>50, D12>50, E12>50, F12>50) -> TRUE | C33: =IF(B33=TRUE, "Passed", "Failed") -> Passed | D33: =AND(C12>50, D12>50, E12>50, F12>50) -> FALSE | E33: =IF(D33=TRUE, "Passed", "Failed") -> Failed | F33: =_xlfn.XOR(C12>50, D12>50, E12>50, F12>50) -> TRUE
A34: Preeti | B34: =OR(C13>50, D13>50, E13>50, F13>50) -> TRUE | C34: =IF(B34=TRUE, "Passed", "Failed") -> Passed | D34: =AND(C13>50, D13>50, E13>50, F13>50) -> FALSE | E34: =IF(D34=TRUE, "Passed", "Failed") -> Failed | F34: =_xlfn.XOR(C13>50, D13>50, E13>50, F13>50) -> TRUE

Sheet Speak cells, Show hide formulas
C2: Date | D2: Region | E2: Items | F2: Price
C3: 36531 | D3: East | E3: Footwear | F3: 12000 | I3: No
C4: 36542 | D4: East | E4: Mobile | F4: 35700 | I4: Yes
C5: 36535 | D5: East | E5: Mobile | F5: 42840 | I5: Yes, No
C6: 36530 | D6: East | E6: Smartwatch | F6: 10000 | I6: 10, 20
C7: 36533 | D7: North | E7: Bass Headphones | F7: 32640 | I7: YES, NO
C8: 36526 | D8: North | E8: Beard trimmer | F8: 4000 | H8: =IF(F3>F4, "Yes", "No") -> No | I8: Expensive, Inexpensive
C9: 36528 | D9: North | E9: Deodarant | F9: 8000 | H9: =IF(F3<F4, "Yes", "No") -> Yes
C10: 36544 | D10: North | E10: Deodarant | F10: 8000 | H10: =IF(F7>F13, 10, 20) -> 20
C11: 36541 | D11: North | E11: Mobile | F11: 42840 | H11: =IF(F8<F14, 10, 20) -> 10
C12: 36545 | D12: North | E12: Shaving cream | F12: 8000 | H12: =IF(F6=F17, "YES", "NO") -> NO
C13: 36534 | D13: North | E13: Wrist watch | F13: 48960 | H13: =IF(F17=F6, UPPER(I4), UPPER(I3)) -> NO
C14: 36539 | D14: South | E14: Bass Headphones | F14: 32640 | H14: =IF(F20<>F18, "Expensive", "Inexpensive") -> Inexpensive
C15: 36538 | D15: South | E15: Earbuds | F15: 35700 | H15: =IF(F20>F18, "Expensive", "Inexpensive") -> Inexpensive

Sheet Trace precedents and dependents
B2: Month | C2: Product | D2: Sales
B3: January | C3: Pencils | D3: 1000 | F3: 50
B4: February | C4: Books | D4: 5000 | E4: 40 | G4: =SUM(F3,F5,F7,F9,E4) -> 280 | H4: SUM
B5: March | C5: Colors | D5: 1000 | F5: 10
B6: April | C6: Highlighters | D6: 3500 | E6: 70 | G6: =PRODUCT(F5,F3,E6) -> 35000 | H6: PRODUCT
B7: May | C7: Scales/Rulers | D7: 3000 | F7: 80
B8: June | C8: Notebooks | D8: 4000 | E8: 90 | G8: =AVERAGE(F7,F5,F3,E6,E4,E8) -> 56.666667 | H8: AVERAGE
B9: July | C9: Magazines | D9: 4000 | F9: 100
B10: Total | D10: =SUM(D3:D9) -> 21500 | E10: =SUM(E3:E9) -> 200
G11: COUNT | H11: =COUNT(C3:D9) -> 7
G12: COUNTA | H12: =COUNTA(C3:D9) -> 14
C13: =MIN(D3:D9) -> 1000 | D13: MINIMUM | G13: COUNTBLANK | H13: =COUNTBLANK(E3:F9) -> 7
C14: =MAX(D3:D9) -> 5000 | D14: MAXIMUM

Sheet Evaluate formulas
B2: Formula used | C2: Result
B3: 1*2+3*4/2 | C3: =1*2+3*4/2 -> 8
B4: 2*3+3*4/3 | C4: =2*3+3*4/3 -> 10
B5: 3*4-3*4/2 | C5: =3*4-3*4/2 -> 6
B6: 1*(2+3)*4/3 | C6: =1*(2+3)*4/3 -> 6.6666667
B7: 1*2/5+4-3 | C7: =1*2/5+4-3 -> 1.4

Sheet FOrmula auditing 2
B2: Date | C2: Region | D2: Items | E2: Price | G2: Region | H2: Items | I2: Price
B3: 36533 | C3: East | D3: Bass Headphones | E3: 2000 | G3: North | H3: Wrist watch | I3: <30000
B4: 36531 | C4: East | D4: Footwear | E4: 4000
B5: 36542 | C5: East | D5: Mobile | E5: 6000 | G5: Region | H5: Items | I5: Price | K5: =_xlfn.FORMULATEXT(F13) -> =SUMIFS(E3:E27, C3:C27, "north", D3:D27, "Wrist watch")
B6: 36535 | C6: East | D6: Mobile | E6: 8000 | G6: West | H6: Beard trimmer | I6: >40000
B7: 36530 | C7: East | D7: Smartwatch | E7: 10000
B8: 36531 | C8: East | D8: Smartwatch | E8: 10000 | G8: Region | H8: Items | I8: Price
B9: 36526 | C9: North | D9: Beard trimmer | E9: 14000 | G9: East | H9: Mobile | I9: <=30000
B10: 36528 | C10: North | D10: Deodarant | E10: 16000
B11: 36544 | C11: North | D11: Deodarant | E11: 18000
B12: 36545 | C12: North | D12: Shaving cream | E12: 20000 | F12: SUMIFS | G12: DSUM | H12: DAVERAGE | I12: DMIN | J12: DMAX
B13: 36534 | C13: North | D13: Wrist watch | E13: 22000 | F13: =SUMIFS(E3:E27, C3:C27, "north", D3:D27, "Wrist watch") -> 47000 | G13: =DSUM(B2:E27, E2, G2:I3) -> 47000 | H13: =DAVERAGE(B2:E27, E2, G2:I3) -> 23500 | I13: =DMIN(B2:E27, E2, G2:I3) -> 22000 | J13: =DMAX(B2:E27, E2, G2:I3) -> 25000
B14: 36535 | C14: North | D14: Wrist watch | E14: 25000
B15: 36539 | C15: South | D15: Bass Headphones | E15: 10000 | G15: =DSUM(B2:E27, E2, G5:I6) -> 107000 | H15: =DAVERAGE(B2:E27, E2, G5:I6) -> 53500 | I15: =DMIN(B2:E27, E2, G5:I6) -> 50000 | J15: =DMAX(B2:E27, E2, G5:I6) -> 57000
B16: 36540 | C16: South | D16: Bass Headphones | E16: HIGHER
B17: 36540 | C17: South | D17: Bass Headphones | E17: 28000
B18: 36538 | C18: South | D18: Earbuds | E18: 30000 | G18: =DSUM(B2:E27, E2, G8:I9) -> 14000 | H18: =DAVERAGE(B2:E27, E2, G8:I9) -> 7000 | I18: =DMIN(B2:E27, E2, G8:I9) -> 6000 | J18: =DMAX(B2:E27, E2, G8:I9) -> 8000
B19: 36537 | C19: South | D19: Jackets | E19: 32000
B20: 36538 | C20: South | D20: Jackets | E20: 20000
B21: 36536 | C21: West | D21: Beard trimmer | E21: 36000 | G21: DCOUNT | H21: DCOUNTA | I21: DPRODUCT
B22: 36537 | C22: West | D22: Beard trimmer | E22: LOWER
B23: 36537 | C23: West | D23: Beard trimmer | E23: 50000 | G23: =DCOUNT(B2:E27, E2, G2:I3) -> 2 | H23: =DCOUNTA(B2:E27, E2, G2:I3) -> 2 | I23: =DPRODUCT(B2:E27, E2, G2:I3) -> 550000000
B24: 36538 | C24: West | D24: Beard trimmer | E24: 57000
B25: 36532 | C25: West | D25: Earbuds | E25: 38000 | G25: =DCOUNT(B2:E27, E2, G5:I6) -> 2 | H25: =DCOUNTA(B2:E27, E2, G5:I6) -> 2 | I25: =DPRODUCT(B2:E27, E2, G5:I6) -> 2850000000
B26: 36547 | C26: West | D26: Mobile | E26: 40000 | G26: =DCOUNT(B2:E27, E2, G5:H6) -> 3 | H26: =DCOUNTA(B2:E27, E2, G5:H6) -> 4 | I26: =DPRODUCT(B2:E27, E2, G5:H6) -> 102600000000000
B27: 36529 | C27: West | D27: Shaving cream | E27: 42000
G28: =DCOUNT(B2:E27, E2, G8:I9) -> 2 | H28: =DCOUNTA(B2:E27, E2, G8:I9) -> 2 | I28: =DPRODUCT(B2:E27, E2, G8:I9) -> 48000000
E30: =DSUM(#REF!, C19, E19:G20) -> #REF!
C32: =C30 -> 0
G33: =DPRODUCT(#REF!, C12, E12:G13) -> #REF!
F41: =AVERAGE(E3:E27) -> 23391.304
D42: =SUM(E3:E27) -> 538000

Sheet Excel Protection
E5: Formula used | F5: Result
E6: 1*2+3*4/2 | F6: =1*2+3*4/2 -> 8
E7: 2*3+3*4/3 | F7: =2*3+3*4/3 -> 10
E8: 3*4-3*4/2 | F8: =3*4-3*4/2 -> 6
E9: 1*(2+3)*4/3 | F9: =1*(2+3)*4/3 -> 6.6666667
E10: 1*2/5+4-3 | F10: =1*2/5+4-3 -> 1.4

Sheet Text to columns - Delimiter
B3: NAMES | D3: First Name | E3: Last Name | G3: NAMES | I3: First Name | J3: Last Name
B4: Ananya Pandey | D4: Ananya | E4: Pandey | G4: Ananya,,Pandey | I4: Ananya | J4: Pandey
B5: Arohi Sharma | D5: Arohi | E5: Sharma | G5: Arohi,,Sharma | I5: Arohi | J5: Sharma
B6: Mohandas Gandhi | D6: Mohandas | E6: Gandhi | G6: Mohandas,,Gandhi | I6: Mohandas | J6: Gandhi
B7: Mohan Kalra | D7: Mohan | E7: Kalra | G7: Mohan,,Kalra | I7: Mohan | J7: Kalra
B8: Anshu Poonawala | D8: Anshu | E8: Poonawala | G8: Anshu,,Poonawala | I8: Anshu | J8: Poonawala
B9: Rahul Sharma | D9: Rahul | E9: Sharma | G9: Rahul,,Sharma | I9: Rahul | J9: Sharma
B10: Neil Armstrong | D10: Neil | E10: Armstrong | G10: Neil,,Armstrong | I10: Neil | J10: Armstrong
B11: Avnish Agrawal | D11: Avnish | E11: Agrawal | G11: Avnish,,Agrawal | I11: Avnish | J11: Agrawal
B12: Shashank Khan | D12: Shashank | E12: Khan | G12: Shashank,,Khan | I12: Shashank | J12: Khan
B15: NAMES | D15: First Name | E15: Last Name
B16: Ananya,Pandey | D16: Ananya | E16: Pandey | G16: NAMES | H16: S. No. | I16: First Name | J16: Last Name
B17: Arohi,Sharma | D17: Arohi | E17: Sharma | G17: 1. Ananya//Pandey | H17: 1 | I17: Ananya | J17: Pandey
B18: Mohandas,Gandhi | D18: Mohandas | E18: Gandhi | G18: 2. Arohi//Sharma | H18: 2 | I18: Arohi | J18: Sharma
B19: Mohan,Kalra | D19: Mohan | E19: Kalra | G19: 3. Mohandas/Gandhi | H19: 3 | I19: Mohandas | J19: Gandhi
B20: Anshu,Poonawala | D20: Anshu | E20: Poonawala | G20: 4. Mohan//Kalra | H20: 4 | I20: Mohan | J20: Kalra
B21: Rahul,Sharma | D21: Rahul | E21: Sharma | G21: 5. Anshu/Poonawala | H21: 5 | I21: Anshu | J21: Poonawala
B22: Neil,Armstrong | D22: Neil | E22: Armstrong | G22: 6. Rahul//Sharma | H22: 6 | I22: Rahul | J22: Sharma
B23: Avnish,Agrawal | D23: Avnish | E23: Agrawal | G23: 7. Neil/Armstrong | H23: 7 | I23: Neil | J23: Armstrong
B24: Shashank,Khan | D24: Shashank | E24: Khan | G24: 8. Avnish//Agrawal | H24: 8 | I24: Avnish | J24: Agrawal
G25: 9. Shashank/Khan | H25: 9 | I25: Shashank | J25: Khan
B27: NAMES | D27: First Name | E27: Last Name
B28: Ananya;Pandey | D28: Ananya | E28: Pandey
B29: Arohi;Sharma | D29: Arohi | E29: Sharma
B30: Mohandas;Gandhi | D30: Mohandas | E30: Gandhi
B31: Mohan;Kalra | D31: Mohan | E31: Kalra
B32: Anshu;Poonawala | D32: Anshu | E32: Poonawala
B33: Rahul;Sharma | D33: Rahul | E33: Sharma
B34: Neil;Armstrong | D34: Neil | E34: Armstrong
B35: Avnish;Agrawal | D35: Avnish | E35: Agrawal
B36: Shashank;Khan | D36: Shashank | E36: Khan

Sheet Text to columns - Fixed width
B2: Joined | C2: Separate 1 | D2: Separate 2 | H2: Joined | I2: In date format
B3: 2233 | C3: 22 | D3: 33 | H3: 20000815 | I3: 36753
B4: 4455 | C4: 44 | D4: 55 | H4: 20000916 | I4: 36785
B5: 6789 | C5: 67 | D5: 89 | H5: 20001017 | I5: 36816
B6: 2356 | C6: 23 | D6: 56 | H6: 20001118 | I6: 36848
B7: 1227 | C7: 12 | D7: 27 | H7: 20001219 | I7: 36879
B8: 7957 | C8: 79 | D8: 57 | H8: 20001220 | I8: 36880
B9: 1212 | C9: 12 | D9: 12 | H9: 20000721 | I9: 36728
B13: Joined | C13: Separate 1 | D13: Separate 2 | E13: Separate 3 | H13: 15082000 | I13: 36753
B14: 20000815 | C14: 2000 | D14: 08 | E14: 15 | H14: 16092000 | I14: 36785
B15: 20000916 | C15: 2000 | D15: 09 | E15: 16 | H15: 17102000 | I15: 36816
B16: 20001017 | C16: 2000 | D16: 10 | E16: 17 | H16: 18112000 | I16: 36848
B17: 20001118 | C17: 2000 | D17: 11 | E17: 18 | H17: 19122000 | I17: 36879
B18: 20001219 | C18: 2000 | D18: 12 | E18: 19 | H18: 20122000 | I18: 36880
B19: 20001320 | C19: 2000 | D19: 13 | E19: 20 | H19: 21072000 | I19: 36728
B20: 20001421 | C20: 2000 | D20: 14 | E20: 21
B21: 20001522 | C21: 2000 | D21: 15 | E21: 22
B22: 20001623 | C22: 2000 | D22: 16 | E22: 23
B23: 20001724 | C23: 2000 | D23: 17 | E23: 24
B24: 20001825 | C24: 2000 | D24: 18 | E24: 25
B25: 20001926 | C25: 2000 | D25: 19 | E25: 26

Sheet Textsplit function
B1: Randomly arranged words | D1: Items | E1: Prices
B3: Bass Headphones=20000
B4: Earbuds;10000
B5: Shaving Cream;*2000
B6: Jackets:,10000
B7: Beardtrimmer:*&5000
B11: Earbuds=10000, Jackets=4000, beard trimmer=30000
B12: Hairdryer;2000, Shaving cream=1000, Bodylotion*3000, Showergel=2500, Facewash&1000

Sheet Textbefore function
C2: Random text
C4: Bass Headphones=20000 | E4: =_xlfn.TEXTBEFORE(C4, "=") -> #NAME?
C5: Earbuds;10000 | E5: =_xlfn.TEXTBEFORE(C5, ";") -> #NAME?
C6: Shaving Cream;*2000 | E6: =_xlfn.TEXTBEFORE(C6, ";") -> #NAME?
C7: Jackets:,10000 | E7: =_xlfn.TEXTBEFORE(C7, ":") -> #NAME?
C8: Beardtrimmer:*&5000 | E8: =_xlfn.TEXTBEFORE(C8, ":") -> #NAME?
C10: Random text
C11: California = 39648 / 0.03 | D11: =_xlfn.TEXTBEFORE(C11, "=") -> #NAME? | E11: =_xlfn.TEXTBEFORE(C11, " =") -> #NAME? | F11: =_xlfn.TEXTBEFORE(C11, "0.0") -> #NAME? | H11: =LEN(D11) -> #NAME? | I11: =LEN(E11) -> #NAME?
C12: Florida = 22197 / 0.10 | D12: =_xlfn.TEXTBEFORE(C12, "=") -> #NAME? | E12: =_xlfn.TEXTBEFORE(C12, " =") -> #NAME? | F12: =_xlfn.TEXTBEFORE(C12, " ", 3) -> #NAME? | H12: =LEN(D12) -> #NAME? | I12: =LEN(E12) -> #NAME?
C13: New York = 19191 / -0.04 | D13: =_xlfn.TEXTBEFORE(C13, "=") -> #NAME? | E13: =_xlfn.TEXTBEFORE(C13, " =") -> #NAME? | F13: =_xlfn.TEXTBEFORE(C13, " ", 3) -> #NAME? | H13: =LEN(D13) -> #NAME? | I13: =LEN(E13) -> #NAME?
C14: Illinois = 12518 / -0.04 | D14: =_xlfn.TEXTBEFORE(C14, "=") -> #NAME? | E14: =_xlfn.TEXTBEFORE(C14, " =") -> #NAME? | F14: =_xlfn.TEXTBEFORE(C14, " ", 3) -> #NAME? | H14: =LEN(D14) -> #NAME? | I14: =LEN(E14) -> #NAME?
C15: Georgia = 36299 / 0.09 | D15: =_xlfn.TEXTBEFORE(C15, "=") -> #NAME? | E15: =_xlfn.TEXTBEFORE(C15, " =") -> #NAME? | F15: =_xlfn.TEXTBEFORE(C15, " ", 3) -> #NAME? | H15: =LEN(D15) -> #NAME? | I15: =LEN(E15) -> #NAME?
C16: Virginia = 86321 / 0.5 | D16: =_xlfn.TEXTBEFORE(C16, "=") -> #NAME? | E16: =_xlfn.TEXTBEFORE(C16, " =") -> #NAME? | F16: =_xlfn.TEXTBEFORE(C16, " ", 3) -> #NAME? | H16: =LEN(D16) -> #NAME? | I16: =LEN(E16) -> #NAME?
C17: Oklahoma = 40017 / 0.24 | D17: =_xlfn.TEXTBEFORE(C17, "=") -> #NAME? | E17: =_xlfn.TEXTBEFORE(C17, " =") -> #NAME? | F17: =_xlfn.TEXTBEFORE(C17, " ", 3) -> #NAME? | H17: =LEN(D17) -> #NAME? | I17: =LEN(E17) -> #NAME?
C18: West Virginia = 17571 / -0.78 | D18: =_xlfn.TEXTBEFORE(C18, "=") -> #NAME? | E18: =_xlfn.TEXTBEFORE(C18, " =") -> #NAME? | F18: =_xlfn.TEXTBEFORE(C18, " ", 3) -> #NAME? | H18: =LEN(D18) -> #NAME? | I18: =LEN(E18) -> #NAME?
C19: Hawaii = 14009 / -0.1 | D19: =_xlfn.TEXTBEFORE(C19, "=") -> #NAME? | E19: =_xlfn.TEXTBEFORE(C19, " =") -> #NAME? | F19: =_xlfn.TEXTBEFORE(C19, " ", 3) -> #NAME? | H19: =LEN(D19) -> #NAME? | I19: =LEN(E19) -> #NAME?
C20: New Hampshire = 13789 / 0.5 | D20: =_xlfn.TEXTBEFORE(C20, "=") -> #NAME? | E20: =_xlfn.TEXTBEFORE(C20, " =") -> #NAME? | F20: =_xlfn.TEXTBEFORE(C20, " ", 3) -> #NAME? | H20: =LEN(D20) -> #NAME? | I20: =LEN(E20) -> #NAME?
C21: Maine = 15967 / 0.08 | D21: =_xlfn.TEXTBEFORE(C21, "=") -> #NAME? | E21: =_xlfn.TEXTBEFORE(C21, " =") -> #NAME? | F21: =_xlfn.TEXTBEFORE(C21, " ", 3) -> #NAME? | H21: =LEN(D21) -> #NAME? | I21: =LEN(E21) -> #NAME?
C22: Montana = 10311 / 0.75 | D22: =_xlfn.TEXTBEFORE(C22, "=") -> #NAME? | E22: =_xlfn.TEXTBEFORE(C22, " =") -> #NAME? | F22: =_xlfn.TEXTBEFORE(C22, " ", 3) -> #NAME? | H22: =LEN(D22) -> #NAME? | I22: =LEN(E22) -> #NAME?
C23: Rhode Island = 10658 / 0.1 | D23: =_xlfn.TEXTBEFORE(C23, "=") -> #NAME? | E23: =_xlfn.TEXTBEFORE(C23, " =") -> #NAME? | F23: =_xlfn.TEXTBEFORE(C23, " ", 3) -> #NAME? | H23: =LEN(D23) -> #NAME? | I23: =LEN(E23) -> #NAME?
C25: Random text
C26: California = 39648 = / 0.03 | D26: =_xlfn.TEXTBEFORE(C26, " =") -> #NAME? | E26: =_xlfn.TEXTBEFORE(C26, " =", 2) -> #NAME? | F26: =_xlfn.TEXTBEFORE(C26, " =", 2) -> #NAME?
C27: Florida = 22197 = / 0.10 | D27: =_xlfn.TEXTBEFORE(C27, " =") -> #NAME? | E27: =_xlfn.TEXTBEFORE(C27, " =", 2) -> #NAME? | F27: =_xlfn.TEXTBEFORE(C27, " =", 20) -> #NAME?
C28: New York = 19191 = / -0.04 | D28: =_xlfn.TEXTBEFORE(C28, " =") -> #NAME? | E28: =_xlfn.TEXTBEFORE(C28, " =", 2) -> #NAME? | F28: =_xlfn.TEXTBEFORE(C28, " =", 3) -> #NAME?
C29: Illinois = 12518 = / -0.04 | D29: =_xlfn.TEXTBEFORE(C29, " =") -> #NAME? | E29: =_xlfn.TEXTBEFORE(C29, " =", 2) -> #NAME? | F29: =_xlfn.TEXTBEFORE(C29, " =", 2) -> #NAME?
C30: Georgia = 36299 = / 0.09 | D30: =_xlfn.TEXTBEFORE(C30, " =") -> #NAME? | E30: =_xlfn.TEXTBEFORE(C30, " =", 2) -> #NAME? | F30: =_xlfn.TEXTBEFORE(C30, " =", 2) -> #NAME?
C31: Virginia = 86321 = / 0.5 | D31: =_xlfn.TEXTBEFORE(C31, " =") -> #NAME? | E31: =_xlfn.TEXTBEFORE(C31, " =", 2) -> #NAME? | F31: =_xlfn.TEXTBEFORE(C31, " =", 2) -> #NAME?
C32: Oklahoma = 40017 / = 0.24 | D32: =_xlfn.TEXTBEFORE(C32, " =") -> #NAME? | E32: =_xlfn.TEXTBEFORE(C32, " =", 2) -> #NAME? | F32: =_xlfn.TEXTBEFORE(C32, " =", 2) -> #NAME?
C33: West Virginia = 17571 = / -0.78 | D33: =_xlfn.TEXTBEFORE(C33, " =") -> #NAME? | E33: =_xlfn.TEXTBEFORE(C33, " =", 2) -> #NAME? | F33: =_xlfn.TEXTBEFORE(C33, " =", 2) -> #NAME?
C34: Hawaii = 14009 / = -0.1 | D34: =_xlfn.TEXTBEFORE(C34, " =") -> #NAME? | E34: =_xlfn.TEXTBEFORE(C34, " =", 2) -> #NAME? | F34: =_xlfn.TEXTBEFORE(C34, " =", 2) -> #NAME?
C35: New Hampshire = 13789 = / 0.5 | D35: =_xlfn.TEXTBEFORE(C35, " =") -> #NAME? | E35: =_xlfn.TEXTBEFORE(C35, " =", 2) -> #NAME? | F35: =_xlfn.TEXTBEFORE(C35, " =", 2) -> #NAME?
C36: Maine = 15967 / = 0.08 | D36: =_xlfn.TEXTBEFORE(C36, " =") -> #NAME? | E36: =_xlfn.TEXTBEFORE(C36, " =", 2) -> #NAME? | F36: =_xlfn.TEXTBEFORE(C36, " =", 2) -> #NAME?
C37: Montana = 10311 = / 0.75 | D37: =_xlfn.TEXTBEFORE(C37, " =") -> #NAME? | E37: =_xlfn.TEXTBEFORE(C37, " =", 2) -> #NAME? | F37: =_xlfn.TEXTBEFORE(C37, " =", 2) -> #NAME?
C38: Rhode Island = 10658 / = 0.1 | D38: =_xlfn.TEXTBEFORE(C38, " =") -> #NAME? | E38: =_xlfn.TEXTBEFORE(C38, " =", 2) -> #NAME? | F38: =_xlfn.TEXTBEFORE(C38, " =", 2) -> #NAME?

Sheet Textafter function
C2: Random text
C4: Bass Headphones=20000 | E4: =_xlfn.TEXTAFTER(C4, "=") -> #NAME?
C5: Earbuds;10000 | E5: =_xlfn.TEXTAFTER(C5, ";") -> #NAME?
C6: Shaving Cream;*2000 | E6: =_xlfn.TEXTAFTER(C6, "*") -> #NAME?
C7: Jackets:,10000 | E7: =_xlfn.TEXTAFTER(C7, ",") -> #NAME?
C8: Beardtrimmer:*&5000 | E8: =_xlfn.TEXTAFTER(C8, "&") -> #NAME?
C10: Random text | E10: Number | F10: Growth rate | H10: =_xlfn.TEXTAFTER(C4, "headphones", 1, 1, ,) -> #NAME?
C11: California = 39648 / 0.03 | E11: =_xlfn.TEXTBEFORE(_xlfn.TEXTAFTER(C11, "= "), " /") -> #NAME? | F11: =_xlfn.TEXTAFTER(C11, "/ ") -> #NAME?
C12: Florida = 22197 / 0.10 | E12: =_xlfn.TEXTBEFORE(_xlfn.TEXTAFTER(C12, "= "), " /") -> #NAME? | F12: =_xlfn.TEXTAFTER(C12, "/ ") -> #NAME? | H12: =_xlfn.TEXTAFTER(C4, "headphones", 1, 0, , "Not present") -> #NAME?
C13: New York = 19191 / -0.04 | E13: =_xlfn.TEXTBEFORE(_xlfn.TEXTAFTER(C13, "= "), " /") -> #NAME? | F13: =_xlfn.TEXTAFTER(C13, "/ ") -> #NAME?
C14: Illinois = 12518 / -0.04 | E14: =_xlfn.TEXTBEFORE(_xlfn.TEXTAFTER(C14, "= "), " /") -> #NAME? | F14: =_xlfn.TEXTAFTER(C14, "/ ") -> #NAME?
C15: Georgia = 36299 / 0.09 | E15: =_xlfn.TEXTBEFORE(_xlfn.TEXTAFTER(C15, "= "), " /") -> #NAME? | F15: =_xlfn.TEXTAFTER(C15, "/ ") -> #NAME? | H15: =_xlfn.TEXTAFTER(C11, ";", 1, , , "Its not there") -> #NAME?
C16: Virginia = 86321 / 0.5 | E16: =_xlfn.TEXTBEFORE(_xlfn.TEXTAFTER(C16, "= "), " /") -> #NAME? | F16: =_xlfn.TEXTAFTER(C16, "/ ") -> #NAME? | H16: =_xlfn.TEXTAFTER(C11, ";", 1, , ,) -> #NAME?
C17: Oklahoma = 40017 / 0.24 | E17: =_xlfn.TEXTBEFORE(_xlfn.TEXTAFTER(C17, "= "), " /") -> #NAME? | F17: =_xlfn.TEXTAFTER(C17, "/ ") -> #NAME?
C19: West Virginia = 17571 / -0.78 | E19: =_xlfn.TEXTAFTER(_xlfn.TEXTBEFORE(C19, " /"), "= ") -> #NAME? | F19: =_xlfn.TEXTAFTER(C19, "/ ") -> #NAME?
C20: Hawaii = 14009 / -0.1 | E20: =_xlfn.TEXTAFTER(_xlfn.TEXTBEFORE(C20, " /"), "= ") -> #NAME? | F20: =_xlfn.TEXTAFTER(C20, "/ ") -> #NAME?
C21: New Hampshire = 13789 / 0.5 | E21: =_xlfn.TEXTAFTER(_xlfn.TEXTBEFORE(C21, " /"), "= ") -> #NAME? | F21: =_xlfn.TEXTAFTER(C21, "/ ") -> #NAME?
C22: Maine = 15967 / 0.08 | E22: =_xlfn.TEXTAFTER(_xlfn.TEXTBEFORE(C22, " /"), "= ") -> #NAME? | F22: =_xlfn.TEXTAFTER(C22, "/ ") -> #NAME?
C23: Montana = 10311 / 0.75 | E23: =_xlfn.TEXTAFTER(_xlfn.TEXTBEFORE(C23, " /"), "= ") -> #NAME? | F23: =_xlfn.TEXTAFTER(C23, "/ ") -> #NAME?
C24: Rhode Island = 10658 / 0.1 | E24: =_xlfn.TEXTAFTER(_xlfn.TEXTBEFORE(C24, " /"), "= ") -> #NAME? | F24: =_xlfn.TEXTAFTER(C24, "/ ") -> #NAME?

Sheet Naming ranges
G3: Numbers
G4: 455
G5: 2432
C6: Month | D6: Product | E6: Sales | G6: 6868
C7: January | D7: Pencils | E7: 1000 | G7: 6876
C8: February | D8: Pens | E8: 5000 | G8: 35353
C9: March | D9: Colors | E9: 1000 | G9: 242434
C10: April | D10: Highlighters | E10: 3500 | G10: 344323
C11: May | D11: Scales/Rulers | E11: 3000 | G11: 344343
C12: June | D12: Novels | E12: 4000 | G12: 575343
C13: July | D13: Magazines | E13: 4000 | G13: 55645645
C14: Total | E14: =SUM(E7:E13) -> 21500 | G14: 67786786
E16: =SUM(Sales) -> #REF!
I17: {=Sales*10} -> #REF!
D18: =SUM(Sales) -> #REF!

Sheet Tables in Excel
D2: S.No. | E2: Months | F2: Items | G2: Cost Price | H2: Selling Price
D3: 1 | E3: January | F3: Pencils | G3: 1000 | H3: 1
D4: 2 | E4: February | F4: Pens | G4: 5000 | H4: 2
D5: 3 | E5: March | F5: Colors | G5: 1000 | H5: 3
D6: 4 | E6: April | F6: Highlighters | G6: 3500 | H6: 4
D7: 5 | E7: May | F7: Scales/Rulers | G7: 3000 | H7: 5
D8: 6 | E8: June | F8: Novels | G8: 4000 | H8: 6
D9: 7 | E9: July | F9: Magazines | G9: 4000 | H9: 7
D10: 8 | E10: January | F10: Pencils | G10: 1000 | H10: 8
D11: 9 | E11: February | F11: Pens | G11: 5000 | H11: 9
D12: 10 | E12: March | F12: Colors | G12: 1000
D13: 11 | E13: April | F13: Highlighters | G13: 3500
D14: 12 | E14: May | F14: Scales/Rulers | G14: 3000
D15: 13 | E15: June | F15: Novels | G15: 4000
D16: 14 | E16: July | F16: Magazines | G16: 4000
D17: 15 | E17: January | F17: Pencils | G17: 1000
D18: 16 | E18: February | F18: Pens | G18: 5000
D19: 17 | E19: March | F19: Colors | G19: 1000
D20: 18 | E20: April | F20: Highlighters | G20: 3500
D21: 19 | E21: May | F21: Scales/Rulers | G21: 3000
